[2025-09-09T14:52:58.250+0000] {taskinstance.py:1956} INFO - Dependencies all met for dep_context=non-requeueable deps ti=<TaskInstance: banvic_etl.extract_sql_db manual__2025-09-04T20:21:36.333567+00:00 [queued]>
[2025-09-09T14:52:58.386+0000] {taskinstance.py:1956} INFO - Dependencies all met for dep_context=requeueable deps ti=<TaskInstance: banvic_etl.extract_sql_db manual__2025-09-04T20:21:36.333567+00:00 [queued]>
[2025-09-09T14:52:58.398+0000] {taskinstance.py:2170} INFO - Starting attempt 6 of 7
[2025-09-09T14:52:58.843+0000] {taskinstance.py:2191} INFO - Executing <Task(PythonOperator): extract_sql_db> on 2025-09-04 20:21:36.333567+00:00
[2025-09-09T14:52:59.027+0000] {standard_task_runner.py:60} INFO - Started process 366 to run task
[2025-09-09T14:52:59.112+0000] {standard_task_runner.py:87} INFO - Running: ['airflow', 'tasks', 'run', 'banvic_etl', 'extract_sql_db', 'manual__2025-09-04T20:21:36.333567+00:00', '--job-id', '101', '--raw', '--subdir', 'DAGS_FOLDER/bavic_dag.py', '--cfg-path', '/tmp/tmp19t38_9g']
[2025-09-09T14:52:59.140+0000] {standard_task_runner.py:88} INFO - Job 101: Subtask extract_sql_db
[2025-09-09T14:53:00.747+0000] {task_command.py:423} INFO - Running <TaskInstance: banvic_etl.extract_sql_db manual__2025-09-04T20:21:36.333567+00:00 [running]> on host 9948058d4968
[2025-09-09T14:53:02.270+0000] {taskinstance.py:2480} INFO - Exporting env vars: AIRFLOW_CTX_DAG_OWNER='Paulo' AIRFLOW_CTX_DAG_ID='banvic_etl' AIRFLOW_CTX_TASK_ID='extract_sql_db' AIRFLOW_CTX_EXECUTION_DATE='2025-09-04T20:21:36.333567+00:00' AIRFLOW_CTX_TRY_NUMBER='6' AIRFLOW_CTX_DAG_RUN_ID='manual__2025-09-04T20:21:36.333567+00:00'
[2025-09-09T14:53:03.068+0000] {logging_mixin.py:188} WARNING - /opt/airflow/scripts/extract_helpers.py:33 UserWarning: pandas only supports SQLAlchemy connectable (engine/connection) or database string URI or sqlite3 DBAPI2 connection. Other DBAPI2 objects are not tested. Please consider using SQLAlchemy.
[2025-09-09T14:53:03.251+0000] {taskinstance.py:2698} ERROR - Task failed with exception
Traceback (most recent call last):
  File "/home/airflow/.local/lib/python3.11/site-packages/airflow/models/taskinstance.py", line 433, in _execute_task
    result = execute_callable(context=context, **execute_callable_kwargs)
             ^^^^^^^^^^^^^^^^^^^^^^^^^^^^^^^^^^^^^^^^^^^^^^^^^^^^^^^^^^^^
  File "/home/airflow/.local/lib/python3.11/site-packages/airflow/operators/python.py", line 199, in execute
    return_value = self.execute_callable()
                   ^^^^^^^^^^^^^^^^^^^^^^^
  File "/home/airflow/.local/lib/python3.11/site-packages/airflow/operators/python.py", line 216, in execute_callable
    return self.python_callable(*self.op_args, **self.op_kwargs)
           ^^^^^^^^^^^^^^^^^^^^^^^^^^^^^^^^^^^^^^^^^^^^^^^^^^^^^
  File "/opt/airflow/scripts/extract_helpers.py", line 36, in extract_sql_db
    os.replace(tmp, os.path.join(out_dir_base, f'{table}.csv'))
FileNotFoundError: [Errno 2] No such file or directory: '/opt/airflow/outputs/2025-09-04/sql/agencias.tmp' -> '/opt/airflow/outputs/2025-09-04/sql/agencias.csv'
[2025-09-09T14:53:03.489+0000] {taskinstance.py:1138} INFO - Marking task as UP_FOR_RETRY. dag_id=banvic_etl, task_id=extract_sql_db, execution_date=20250904T202136, start_date=20250909T145258, end_date=20250909T145303
[2025-09-09T14:53:03.600+0000] {standard_task_runner.py:107} ERROR - Failed to execute job 101 for task extract_sql_db ([Errno 2] No such file or directory: '/opt/airflow/outputs/2025-09-04/sql/agencias.tmp' -> '/opt/airflow/outputs/2025-09-04/sql/agencias.csv'; 366)
[2025-09-09T14:53:03.694+0000] {local_task_job_runner.py:234} INFO - Task exited with return code 1
[2025-09-09T14:53:04.169+0000] {taskinstance.py:3280} INFO - 0 downstream tasks scheduled from follow-on schedule check
