[2025-09-04T20:29:40.631+0000] {taskinstance.py:1956} INFO - Dependencies all met for dep_context=non-requeueable deps ti=<TaskInstance: banvic_etl.extract_sql_db manual__2025-09-04T16:49:13.653051+00:00 [queued]>
[2025-09-04T20:29:40.644+0000] {taskinstance.py:1956} INFO - Dependencies all met for dep_context=requeueable deps ti=<TaskInstance: banvic_etl.extract_sql_db manual__2025-09-04T16:49:13.653051+00:00 [queued]>
[2025-09-04T20:29:40.645+0000] {taskinstance.py:2170} INFO - Starting attempt 5 of 6
[2025-09-04T20:29:40.668+0000] {taskinstance.py:2191} INFO - Executing <Task(PythonOperator): extract_sql_db> on 2025-09-04 16:49:13.653051+00:00
[2025-09-04T20:29:40.684+0000] {standard_task_runner.py:60} INFO - Started process 340 to run task
[2025-09-04T20:29:40.696+0000] {standard_task_runner.py:87} INFO - Running: ['airflow', 'tasks', 'run', 'banvic_etl', 'extract_sql_db', 'manual__2025-09-04T16:49:13.653051+00:00', '--job-id', '42', '--raw', '--subdir', 'DAGS_FOLDER/banvic_dag.py', '--cfg-path', '/tmp/tmp303m_6_z']
[2025-09-04T20:29:40.701+0000] {standard_task_runner.py:88} INFO - Job 42: Subtask extract_sql_db
[2025-09-04T20:29:40.929+0000] {task_command.py:423} INFO - Running <TaskInstance: banvic_etl.extract_sql_db manual__2025-09-04T16:49:13.653051+00:00 [running]> on host c181d38c454f
[2025-09-04T20:29:41.247+0000] {taskinstance.py:2480} INFO - Exporting env vars: AIRFLOW_CTX_DAG_OWNER='you' AIRFLOW_CTX_DAG_ID='banvic_etl' AIRFLOW_CTX_TASK_ID='extract_sql_db' AIRFLOW_CTX_EXECUTION_DATE='2025-09-04T16:49:13.653051+00:00' AIRFLOW_CTX_TRY_NUMBER='5' AIRFLOW_CTX_DAG_RUN_ID='manual__2025-09-04T16:49:13.653051+00:00'
[2025-09-04T20:29:41.257+0000] {taskinstance.py:2698} ERROR - Task failed with exception
Traceback (most recent call last):
  File "/home/airflow/.local/lib/python3.11/site-packages/airflow/models/taskinstance.py", line 433, in _execute_task
    result = execute_callable(context=context, **execute_callable_kwargs)
             ^^^^^^^^^^^^^^^^^^^^^^^^^^^^^^^^^^^^^^^^^^^^^^^^^^^^^^^^^^^^
  File "/home/airflow/.local/lib/python3.11/site-packages/airflow/operators/python.py", line 199, in execute
    return_value = self.execute_callable()
                   ^^^^^^^^^^^^^^^^^^^^^^^
  File "/home/airflow/.local/lib/python3.11/site-packages/airflow/operators/python.py", line 216, in execute_callable
    return self.python_callable(*self.op_args, **self.op_kwargs)
           ^^^^^^^^^^^^^^^^^^^^^^^^^^^^^^^^^^^^^^^^^^^^^^^^^^^^^
  File "/opt/airflow/scripts/extract_helpers.py", line 20, in extract_sql_db
    conn = psycopg2.connect (
           ^^^^^^^^^^^^^^^^^^
  File "/home/airflow/.local/lib/python3.11/site-packages/psycopg2/__init__.py", line 122, in connect
    conn = _connect(dsn, connection_factory=connection_factory, **kwasync)
           ^^^^^^^^^^^^^^^^^^^^^^^^^^^^^^^^^^^^^^^^^^^^^^^^^^^^^^^^^^^^^^^
psycopg2.OperationalError: connection to server at "localhost" (::1), port 55432 failed: Connection refused
	Is the server running on that host and accepting TCP/IP connections?
connection to server at "localhost" (127.0.0.1), port 55432 failed: Connection refused
	Is the server running on that host and accepting TCP/IP connections?

[2025-09-04T20:29:41.327+0000] {taskinstance.py:1138} INFO - Marking task as UP_FOR_RETRY. dag_id=banvic_etl, task_id=extract_sql_db, execution_date=20250904T164913, start_date=20250904T202940, end_date=20250904T202941
[2025-09-04T20:29:41.370+0000] {standard_task_runner.py:107} ERROR - Failed to execute job 42 for task extract_sql_db (connection to server at "localhost" (::1), port 55432 failed: Connection refused
	Is the server running on that host and accepting TCP/IP connections?
connection to server at "localhost" (127.0.0.1), port 55432 failed: Connection refused
	Is the server running on that host and accepting TCP/IP connections?
; 340)
[2025-09-04T20:29:41.403+0000] {local_task_job_runner.py:234} INFO - Task exited with return code 1
[2025-09-04T20:29:41.478+0000] {taskinstance.py:3280} INFO - 0 downstream tasks scheduled from follow-on schedule check
