[2025-09-04T20:29:30.546+0000] {taskinstance.py:1956} INFO - Dependencies all met for dep_context=non-requeueable deps ti=<TaskInstance: banvic_etl.extract_sql_db manual__2025-09-04T16:11:37.161994+00:00 [queued]>
[2025-09-04T20:29:30.562+0000] {taskinstance.py:1956} INFO - Dependencies all met for dep_context=requeueable deps ti=<TaskInstance: banvic_etl.extract_sql_db manual__2025-09-04T16:11:37.161994+00:00 [queued]>
[2025-09-04T20:29:30.562+0000] {taskinstance.py:2170} INFO - Starting attempt 5 of 6
[2025-09-04T20:29:30.588+0000] {taskinstance.py:2191} INFO - Executing <Task(PythonOperator): extract_sql_db> on 2025-09-04 16:11:37.161994+00:00
[2025-09-04T20:29:30.602+0000] {standard_task_runner.py:60} INFO - Started process 328 to run task
[2025-09-04T20:29:30.609+0000] {standard_task_runner.py:87} INFO - Running: ['airflow', 'tasks', 'run', 'banvic_etl', 'extract_sql_db', 'manual__2025-09-04T16:11:37.161994+00:00', '--job-id', '39', '--raw', '--subdir', 'DAGS_FOLDER/banvic_dag.py', '--cfg-path', '/tmp/tmp66rq_cb5']
[2025-09-04T20:29:30.616+0000] {standard_task_runner.py:88} INFO - Job 39: Subtask extract_sql_db
[2025-09-04T20:29:30.869+0000] {task_command.py:423} INFO - Running <TaskInstance: banvic_etl.extract_sql_db manual__2025-09-04T16:11:37.161994+00:00 [running]> on host c181d38c454f
[2025-09-04T20:29:31.192+0000] {taskinstance.py:2480} INFO - Exporting env vars: AIRFLOW_CTX_DAG_OWNER='you' AIRFLOW_CTX_DAG_ID='banvic_etl' AIRFLOW_CTX_TASK_ID='extract_sql_db' AIRFLOW_CTX_EXECUTION_DATE='2025-09-04T16:11:37.161994+00:00' AIRFLOW_CTX_TRY_NUMBER='5' AIRFLOW_CTX_DAG_RUN_ID='manual__2025-09-04T16:11:37.161994+00:00'
[2025-09-04T20:29:31.201+0000] {taskinstance.py:2698} ERROR - Task failed with exception
Traceback (most recent call last):
  File "/home/airflow/.local/lib/python3.11/site-packages/airflow/models/taskinstance.py", line 433, in _execute_task
    result = execute_callable(context=context, **execute_callable_kwargs)
             ^^^^^^^^^^^^^^^^^^^^^^^^^^^^^^^^^^^^^^^^^^^^^^^^^^^^^^^^^^^^
  File "/home/airflow/.local/lib/python3.11/site-packages/airflow/operators/python.py", line 199, in execute
    return_value = self.execute_callable()
                   ^^^^^^^^^^^^^^^^^^^^^^^
  File "/home/airflow/.local/lib/python3.11/site-packages/airflow/operators/python.py", line 216, in execute_callable
    return self.python_callable(*self.op_args, **self.op_kwargs)
           ^^^^^^^^^^^^^^^^^^^^^^^^^^^^^^^^^^^^^^^^^^^^^^^^^^^^^
  File "/opt/airflow/scripts/extract_helpers.py", line 20, in extract_sql_db
    conn = psycopg2.connect (
           ^^^^^^^^^^^^^^^^^^
  File "/home/airflow/.local/lib/python3.11/site-packages/psycopg2/__init__.py", line 122, in connect
    conn = _connect(dsn, connection_factory=connection_factory, **kwasync)
           ^^^^^^^^^^^^^^^^^^^^^^^^^^^^^^^^^^^^^^^^^^^^^^^^^^^^^^^^^^^^^^^
psycopg2.OperationalError: connection to server at "localhost" (::1), port 55432 failed: Connection refused
	Is the server running on that host and accepting TCP/IP connections?
connection to server at "localhost" (127.0.0.1), port 55432 failed: Connection refused
	Is the server running on that host and accepting TCP/IP connections?

[2025-09-04T20:29:31.269+0000] {taskinstance.py:1138} INFO - Marking task as UP_FOR_RETRY. dag_id=banvic_etl, task_id=extract_sql_db, execution_date=20250904T161137, start_date=20250904T202930, end_date=20250904T202931
[2025-09-04T20:29:31.300+0000] {standard_task_runner.py:107} ERROR - Failed to execute job 39 for task extract_sql_db (connection to server at "localhost" (::1), port 55432 failed: Connection refused
	Is the server running on that host and accepting TCP/IP connections?
connection to server at "localhost" (127.0.0.1), port 55432 failed: Connection refused
	Is the server running on that host and accepting TCP/IP connections?
; 328)
[2025-09-04T20:29:31.350+0000] {local_task_job_runner.py:234} INFO - Task exited with return code 1
[2025-09-04T20:29:31.444+0000] {taskinstance.py:3280} INFO - 0 downstream tasks scheduled from follow-on schedule check
