[2025-09-04T20:21:38.537+0000] {taskinstance.py:1956} INFO - Dependencies all met for dep_context=non-requeueable deps ti=<TaskInstance: banvic_etl.extract_csv manual__2025-09-04T16:49:13.653051+00:00 [queued]>
[2025-09-04T20:21:38.556+0000] {taskinstance.py:1956} INFO - Dependencies all met for dep_context=requeueable deps ti=<TaskInstance: banvic_etl.extract_csv manual__2025-09-04T16:49:13.653051+00:00 [queued]>
[2025-09-04T20:21:38.558+0000] {taskinstance.py:2170} INFO - Starting attempt 3 of 4
[2025-09-04T20:21:38.599+0000] {taskinstance.py:2191} INFO - Executing <Task(PythonOperator): extract_csv> on 2025-09-04 16:49:13.653051+00:00
[2025-09-04T20:21:38.620+0000] {standard_task_runner.py:60} INFO - Started process 204 to run task
[2025-09-04T20:21:38.631+0000] {standard_task_runner.py:87} INFO - Running: ['airflow', 'tasks', 'run', 'banvic_etl', 'extract_csv', 'manual__2025-09-04T16:49:13.653051+00:00', '--job-id', '23', '--raw', '--subdir', 'DAGS_FOLDER/banvic_dag.py', '--cfg-path', '/tmp/tmpkad_92xq']
[2025-09-04T20:21:38.637+0000] {standard_task_runner.py:88} INFO - Job 23: Subtask extract_csv
[2025-09-04T20:21:38.935+0000] {task_command.py:423} INFO - Running <TaskInstance: banvic_etl.extract_csv manual__2025-09-04T16:49:13.653051+00:00 [running]> on host c181d38c454f
[2025-09-04T20:21:39.437+0000] {taskinstance.py:2480} INFO - Exporting env vars: AIRFLOW_CTX_DAG_OWNER='you' AIRFLOW_CTX_DAG_ID='banvic_etl' AIRFLOW_CTX_TASK_ID='extract_csv' AIRFLOW_CTX_EXECUTION_DATE='2025-09-04T16:49:13.653051+00:00' AIRFLOW_CTX_TRY_NUMBER='3' AIRFLOW_CTX_DAG_RUN_ID='manual__2025-09-04T16:49:13.653051+00:00'
[2025-09-04T20:21:39.704+0000] {taskinstance.py:2698} ERROR - Task failed with exception
Traceback (most recent call last):
  File "/home/airflow/.local/lib/python3.11/site-packages/airflow/models/taskinstance.py", line 433, in _execute_task
    result = execute_callable(context=context, **execute_callable_kwargs)
             ^^^^^^^^^^^^^^^^^^^^^^^^^^^^^^^^^^^^^^^^^^^^^^^^^^^^^^^^^^^^
  File "/home/airflow/.local/lib/python3.11/site-packages/airflow/operators/python.py", line 199, in execute
    return_value = self.execute_callable()
                   ^^^^^^^^^^^^^^^^^^^^^^^
  File "/home/airflow/.local/lib/python3.11/site-packages/airflow/operators/python.py", line 216, in execute_callable
    return self.python_callable(*self.op_args, **self.op_kwargs)
           ^^^^^^^^^^^^^^^^^^^^^^^^^^^^^^^^^^^^^^^^^^^^^^^^^^^^^
  File "/opt/airflow/scripts/extract_helpers.py", line 12, in extract_csv
    os.replace(tmp, os.path.join(dest_dir, 'transacoes.csv'))  # atomic
    ^^^^^^^^^^^^^^^^^^^^^^^^^^^^^^^^^^^^^^^^^^^^^^^^^^^^^^^^^
FileNotFoundError: [Errno 2] No such file or directory: '/opt/airflow/outputs/2025-09-04/csv/transacoes.tmp' -> '/opt/airflow/outputs/2025-09-04/csv/transacoes.csv'
[2025-09-04T20:21:39.771+0000] {taskinstance.py:1138} INFO - Marking task as UP_FOR_RETRY. dag_id=banvic_etl, task_id=extract_csv, execution_date=20250904T164913, start_date=20250904T202138, end_date=20250904T202139
[2025-09-04T20:21:39.816+0000] {standard_task_runner.py:107} ERROR - Failed to execute job 23 for task extract_csv ([Errno 2] No such file or directory: '/opt/airflow/outputs/2025-09-04/csv/transacoes.tmp' -> '/opt/airflow/outputs/2025-09-04/csv/transacoes.csv'; 204)
[2025-09-04T20:21:39.853+0000] {local_task_job_runner.py:234} INFO - Task exited with return code 1
[2025-09-04T20:21:39.955+0000] {taskinstance.py:3280} INFO - 0 downstream tasks scheduled from follow-on schedule check
