[2025-09-04T16:54:18.905+0000] {taskinstance.py:1956} INFO - Dependencies all met for dep_context=non-requeueable deps ti=<TaskInstance: banvic_etl.extract_csv manual__2025-09-04T16:49:13.653051+00:00 [queued]>
[2025-09-04T16:54:18.918+0000] {taskinstance.py:1956} INFO - Dependencies all met for dep_context=requeueable deps ti=<TaskInstance: banvic_etl.extract_csv manual__2025-09-04T16:49:13.653051+00:00 [queued]>
[2025-09-04T16:54:18.919+0000] {taskinstance.py:2170} INFO - Starting attempt 2 of 2
[2025-09-04T16:54:18.948+0000] {taskinstance.py:2191} INFO - Executing <Task(PythonOperator): extract_csv> on 2025-09-04 16:49:13.653051+00:00
[2025-09-04T16:54:18.964+0000] {standard_task_runner.py:60} INFO - Started process 1139 to run task
[2025-09-04T16:54:18.970+0000] {standard_task_runner.py:87} INFO - Running: ['airflow', 'tasks', 'run', 'banvic_etl', 'extract_csv', 'manual__2025-09-04T16:49:13.653051+00:00', '--job-id', '21', '--raw', '--subdir', 'DAGS_FOLDER/banvic_dag.py', '--cfg-path', '/tmp/tmphu0kwfv6']
[2025-09-04T16:54:18.975+0000] {standard_task_runner.py:88} INFO - Job 21: Subtask extract_csv
[2025-09-04T16:54:19.204+0000] {task_command.py:423} INFO - Running <TaskInstance: banvic_etl.extract_csv manual__2025-09-04T16:49:13.653051+00:00 [running]> on host 6a8f9d7ec58e
[2025-09-04T16:54:19.504+0000] {taskinstance.py:2480} INFO - Exporting env vars: AIRFLOW_CTX_DAG_OWNER='you' AIRFLOW_CTX_DAG_ID='banvic_etl' AIRFLOW_CTX_TASK_ID='extract_csv' AIRFLOW_CTX_EXECUTION_DATE='2025-09-04T16:49:13.653051+00:00' AIRFLOW_CTX_TRY_NUMBER='2' AIRFLOW_CTX_DAG_RUN_ID='manual__2025-09-04T16:49:13.653051+00:00'
[2025-09-04T16:54:19.507+0000] {taskinstance.py:2698} ERROR - Task failed with exception
Traceback (most recent call last):
  File "/home/airflow/.local/lib/python3.11/site-packages/airflow/models/taskinstance.py", line 433, in _execute_task
    result = execute_callable(context=context, **execute_callable_kwargs)
             ^^^^^^^^^^^^^^^^^^^^^^^^^^^^^^^^^^^^^^^^^^^^^^^^^^^^^^^^^^^^
  File "/home/airflow/.local/lib/python3.11/site-packages/airflow/operators/python.py", line 199, in execute
    return_value = self.execute_callable()
                   ^^^^^^^^^^^^^^^^^^^^^^^
  File "/home/airflow/.local/lib/python3.11/site-packages/airflow/operators/python.py", line 216, in execute_callable
    return self.python_callable(*self.op_args, **self.op_kwargs)
           ^^^^^^^^^^^^^^^^^^^^^^^^^^^^^^^^^^^^^^^^^^^^^^^^^^^^^
  File "/opt/airflow/scripts/extract_helpers.py", line 9, in extract_csv
    os.makedirs(dest_dir, exist_ok=True)
  File "<frozen os>", line 215, in makedirs
  File "<frozen os>", line 215, in makedirs
  File "<frozen os>", line 215, in makedirs
  [Previous line repeated 2 more times]
  File "<frozen os>", line 225, in makedirs
PermissionError: [Errno 13] Permission denied: '/path'
[2025-09-04T16:54:19.558+0000] {taskinstance.py:1138} INFO - Marking task as FAILED. dag_id=banvic_etl, task_id=extract_csv, execution_date=20250904T164913, start_date=20250904T165418, end_date=20250904T165419
[2025-09-04T16:54:19.597+0000] {standard_task_runner.py:107} ERROR - Failed to execute job 21 for task extract_csv ([Errno 13] Permission denied: '/path'; 1139)
[2025-09-04T16:54:19.628+0000] {local_task_job_runner.py:234} INFO - Task exited with return code 1
[2025-09-04T16:54:19.730+0000] {taskinstance.py:3280} INFO - 0 downstream tasks scheduled from follow-on schedule check
