[2025-09-09T14:52:57.880+0000] {taskinstance.py:1956} INFO - Dependencies all met for dep_context=non-requeueable deps ti=<TaskInstance: banvic_etl.extract_csv scheduled__2025-09-04T04:35:00+00:00 [queued]>
[2025-09-09T14:52:57.937+0000] {taskinstance.py:1956} INFO - Dependencies all met for dep_context=requeueable deps ti=<TaskInstance: banvic_etl.extract_csv scheduled__2025-09-04T04:35:00+00:00 [queued]>
[2025-09-09T14:52:57.938+0000] {taskinstance.py:2170} INFO - Starting attempt 2 of 3
[2025-09-09T14:52:58.063+0000] {taskinstance.py:2191} INFO - Executing <Task(PythonOperator): extract_csv> on 2025-09-04 04:35:00+00:00
[2025-09-09T14:52:58.120+0000] {standard_task_runner.py:60} INFO - Started process 357 to run task
[2025-09-09T14:52:58.269+0000] {standard_task_runner.py:87} INFO - Running: ['airflow', 'tasks', 'run', 'banvic_etl', 'extract_csv', 'scheduled__2025-09-04T04:35:00+00:00', '--job-id', '93', '--raw', '--subdir', 'DAGS_FOLDER/bavic_dag.py', '--cfg-path', '/tmp/tmp2by7g3yb']
[2025-09-09T14:52:58.308+0000] {standard_task_runner.py:88} INFO - Job 93: Subtask extract_csv
[2025-09-09T14:53:00.347+0000] {task_command.py:423} INFO - Running <TaskInstance: banvic_etl.extract_csv scheduled__2025-09-04T04:35:00+00:00 [running]> on host 9948058d4968
[2025-09-09T14:53:01.965+0000] {taskinstance.py:2480} INFO - Exporting env vars: AIRFLOW_CTX_DAG_OWNER='Paulo' AIRFLOW_CTX_DAG_ID='banvic_etl' AIRFLOW_CTX_TASK_ID='extract_csv' AIRFLOW_CTX_EXECUTION_DATE='2025-09-04T04:35:00+00:00' AIRFLOW_CTX_TRY_NUMBER='2' AIRFLOW_CTX_DAG_RUN_ID='scheduled__2025-09-04T04:35:00+00:00'
[2025-09-09T14:53:02.728+0000] {taskinstance.py:2698} ERROR - Task failed with exception
Traceback (most recent call last):
  File "/home/airflow/.local/lib/python3.11/site-packages/airflow/models/taskinstance.py", line 433, in _execute_task
    result = execute_callable(context=context, **execute_callable_kwargs)
             ^^^^^^^^^^^^^^^^^^^^^^^^^^^^^^^^^^^^^^^^^^^^^^^^^^^^^^^^^^^^
  File "/home/airflow/.local/lib/python3.11/site-packages/airflow/operators/python.py", line 199, in execute
    return_value = self.execute_callable()
                   ^^^^^^^^^^^^^^^^^^^^^^^
  File "/home/airflow/.local/lib/python3.11/site-packages/airflow/operators/python.py", line 216, in execute_callable
    return self.python_callable(*self.op_args, **self.op_kwargs)
           ^^^^^^^^^^^^^^^^^^^^^^^^^^^^^^^^^^^^^^^^^^^^^^^^^^^^^
  File "/opt/airflow/scripts/extract_helpers.py", line 12, in extract_csv
    os.replace(tmp, os.path.join(dest_dir, 'transacoes.csv'))
FileNotFoundError: [Errno 2] No such file or directory: '/opt/airflow/outputs/2025-09-04/csv/transacoes.tmp' -> '/opt/airflow/outputs/2025-09-04/csv/transacoes.csv'
[2025-09-09T14:53:02.917+0000] {taskinstance.py:1138} INFO - Marking task as UP_FOR_RETRY. dag_id=banvic_etl, task_id=extract_csv, execution_date=20250904T043500, start_date=20250909T145257, end_date=20250909T145302
[2025-09-09T14:53:03.185+0000] {standard_task_runner.py:107} ERROR - Failed to execute job 93 for task extract_csv ([Errno 2] No such file or directory: '/opt/airflow/outputs/2025-09-04/csv/transacoes.tmp' -> '/opt/airflow/outputs/2025-09-04/csv/transacoes.csv'; 357)
[2025-09-09T14:53:03.273+0000] {local_task_job_runner.py:234} INFO - Task exited with return code 1
[2025-09-09T14:53:03.568+0000] {taskinstance.py:3280} INFO - 0 downstream tasks scheduled from follow-on schedule check
