[2025-09-05T00:16:38.495+0000] {taskinstance.py:1956} INFO - Dependencies all met for dep_context=non-requeueable deps ti=<TaskInstance: banvic_etl.extract_sql_db manual__2025-09-05T00:11:34.425860+00:00 [queued]>
[2025-09-05T00:16:38.508+0000] {taskinstance.py:1956} INFO - Dependencies all met for dep_context=requeueable deps ti=<TaskInstance: banvic_etl.extract_sql_db manual__2025-09-05T00:11:34.425860+00:00 [queued]>
[2025-09-05T00:16:38.509+0000] {taskinstance.py:2170} INFO - Starting attempt 2 of 2
[2025-09-05T00:16:38.531+0000] {taskinstance.py:2191} INFO - Executing <Task(PythonOperator): extract_sql_db> on 2025-09-05 00:11:34.425860+00:00
[2025-09-05T00:16:38.545+0000] {standard_task_runner.py:60} INFO - Started process 437 to run task
[2025-09-05T00:16:38.552+0000] {standard_task_runner.py:87} INFO - Running: ['airflow', 'tasks', 'run', 'banvic_etl', 'extract_sql_db', 'manual__2025-09-05T00:11:34.425860+00:00', '--job-id', '52', '--raw', '--subdir', 'DAGS_FOLDER/banvic_dag.py', '--cfg-path', '/tmp/tmp6_6too2u']
[2025-09-05T00:16:38.557+0000] {standard_task_runner.py:88} INFO - Job 52: Subtask extract_sql_db
[2025-09-05T00:16:38.771+0000] {task_command.py:423} INFO - Running <TaskInstance: banvic_etl.extract_sql_db manual__2025-09-05T00:11:34.425860+00:00 [running]> on host 4aa2e47e4b7d
[2025-09-05T00:16:39.093+0000] {taskinstance.py:2480} INFO - Exporting env vars: AIRFLOW_CTX_DAG_OWNER='you' AIRFLOW_CTX_DAG_ID='banvic_etl' AIRFLOW_CTX_TASK_ID='extract_sql_db' AIRFLOW_CTX_EXECUTION_DATE='2025-09-05T00:11:34.425860+00:00' AIRFLOW_CTX_TRY_NUMBER='2' AIRFLOW_CTX_DAG_RUN_ID='manual__2025-09-05T00:11:34.425860+00:00'
[2025-09-05T00:16:39.103+0000] {taskinstance.py:2698} ERROR - Task failed with exception
Traceback (most recent call last):
  File "/home/airflow/.local/lib/python3.11/site-packages/airflow/models/taskinstance.py", line 433, in _execute_task
    result = execute_callable(context=context, **execute_callable_kwargs)
             ^^^^^^^^^^^^^^^^^^^^^^^^^^^^^^^^^^^^^^^^^^^^^^^^^^^^^^^^^^^^
  File "/home/airflow/.local/lib/python3.11/site-packages/airflow/operators/python.py", line 199, in execute
    return_value = self.execute_callable()
                   ^^^^^^^^^^^^^^^^^^^^^^^
  File "/home/airflow/.local/lib/python3.11/site-packages/airflow/operators/python.py", line 216, in execute_callable
    return self.python_callable(*self.op_args, **self.op_kwargs)
           ^^^^^^^^^^^^^^^^^^^^^^^^^^^^^^^^^^^^^^^^^^^^^^^^^^^^^
  File "/opt/airflow/scripts/extract_helpers.py", line 20, in extract_sql_db
    conn = psycopg2.connect (
           ^^^^^^^^^^^^^^^^^^
  File "/home/airflow/.local/lib/python3.11/site-packages/psycopg2/__init__.py", line 122, in connect
    conn = _connect(dsn, connection_factory=connection_factory, **kwasync)
           ^^^^^^^^^^^^^^^^^^^^^^^^^^^^^^^^^^^^^^^^^^^^^^^^^^^^^^^^^^^^^^^
psycopg2.OperationalError: connection to server at "db" (172.18.0.4), port 55432 failed: Connection refused
	Is the server running on that host and accepting TCP/IP connections?

[2025-09-05T00:16:39.164+0000] {taskinstance.py:1138} INFO - Marking task as FAILED. dag_id=banvic_etl, task_id=extract_sql_db, execution_date=20250905T001134, start_date=20250905T001638, end_date=20250905T001639
[2025-09-05T00:16:39.198+0000] {standard_task_runner.py:107} ERROR - Failed to execute job 52 for task extract_sql_db (connection to server at "db" (172.18.0.4), port 55432 failed: Connection refused
	Is the server running on that host and accepting TCP/IP connections?
; 437)
[2025-09-05T00:16:39.241+0000] {local_task_job_runner.py:234} INFO - Task exited with return code 1
[2025-09-05T00:16:39.327+0000] {taskinstance.py:3280} INFO - 0 downstream tasks scheduled from follow-on schedule check
