[2025-09-09T14:53:07.348+0000] {taskinstance.py:1956} INFO - Dependencies all met for dep_context=non-requeueable deps ti=<TaskInstance: banvic_etl.extract_csv manual__2025-09-06T14:36:34.693198+00:00 [queued]>
[2025-09-09T14:53:07.415+0000] {taskinstance.py:1956} INFO - Dependencies all met for dep_context=requeueable deps ti=<TaskInstance: banvic_etl.extract_csv manual__2025-09-06T14:36:34.693198+00:00 [queued]>
[2025-09-09T14:53:07.420+0000] {taskinstance.py:2170} INFO - Starting attempt 2 of 3
[2025-09-09T14:53:07.487+0000] {taskinstance.py:2191} INFO - Executing <Task(PythonOperator): extract_csv> on 2025-09-06 14:36:34.693198+00:00
[2025-09-09T14:53:07.518+0000] {standard_task_runner.py:60} INFO - Started process 406 to run task
[2025-09-09T14:53:07.538+0000] {standard_task_runner.py:87} INFO - Running: ['airflow', 'tasks', 'run', 'banvic_etl', 'extract_csv', 'manual__2025-09-06T14:36:34.693198+00:00', '--job-id', '116', '--raw', '--subdir', 'DAGS_FOLDER/bavic_dag.py', '--cfg-path', '/tmp/tmpcmng6wzo']
[2025-09-09T14:53:07.548+0000] {standard_task_runner.py:88} INFO - Job 116: Subtask extract_csv
[2025-09-09T14:53:08.185+0000] {task_command.py:423} INFO - Running <TaskInstance: banvic_etl.extract_csv manual__2025-09-06T14:36:34.693198+00:00 [running]> on host 9948058d4968
[2025-09-09T14:53:09.168+0000] {taskinstance.py:2480} INFO - Exporting env vars: AIRFLOW_CTX_DAG_OWNER='Paulo' AIRFLOW_CTX_DAG_ID='banvic_etl' AIRFLOW_CTX_TASK_ID='extract_csv' AIRFLOW_CTX_EXECUTION_DATE='2025-09-06T14:36:34.693198+00:00' AIRFLOW_CTX_TRY_NUMBER='2' AIRFLOW_CTX_DAG_RUN_ID='manual__2025-09-06T14:36:34.693198+00:00'
[2025-09-09T14:53:09.659+0000] {taskinstance.py:2698} ERROR - Task failed with exception
Traceback (most recent call last):
  File "/home/airflow/.local/lib/python3.11/site-packages/airflow/models/taskinstance.py", line 433, in _execute_task
    result = execute_callable(context=context, **execute_callable_kwargs)
             ^^^^^^^^^^^^^^^^^^^^^^^^^^^^^^^^^^^^^^^^^^^^^^^^^^^^^^^^^^^^
  File "/home/airflow/.local/lib/python3.11/site-packages/airflow/operators/python.py", line 199, in execute
    return_value = self.execute_callable()
                   ^^^^^^^^^^^^^^^^^^^^^^^
  File "/home/airflow/.local/lib/python3.11/site-packages/airflow/operators/python.py", line 216, in execute_callable
    return self.python_callable(*self.op_args, **self.op_kwargs)
           ^^^^^^^^^^^^^^^^^^^^^^^^^^^^^^^^^^^^^^^^^^^^^^^^^^^^^
  File "/opt/airflow/scripts/extract_helpers.py", line 12, in extract_csv
    os.replace(tmp, os.path.join(dest_dir, 'transacoes.csv'))
FileNotFoundError: [Errno 2] No such file or directory: '/opt/airflow/outputs/2025-09-06/csv/transacoes.tmp' -> '/opt/airflow/outputs/2025-09-06/csv/transacoes.csv'
[2025-09-09T14:53:09.854+0000] {taskinstance.py:1138} INFO - Marking task as UP_FOR_RETRY. dag_id=banvic_etl, task_id=extract_csv, execution_date=20250906T143634, start_date=20250909T145307, end_date=20250909T145309
[2025-09-09T14:53:09.936+0000] {standard_task_runner.py:107} ERROR - Failed to execute job 116 for task extract_csv ([Errno 2] No such file or directory: '/opt/airflow/outputs/2025-09-06/csv/transacoes.tmp' -> '/opt/airflow/outputs/2025-09-06/csv/transacoes.csv'; 406)
[2025-09-09T14:53:09.981+0000] {local_task_job_runner.py:234} INFO - Task exited with return code 1
[2025-09-09T14:53:10.335+0000] {taskinstance.py:3280} INFO - 0 downstream tasks scheduled from follow-on schedule check
